<?xml version="1.0" encoding="UTF-8"?>
<testng-results skipped="0" failed="1" ignored="0" total="3" passed="2">
  <reporter-output>
  </reporter-output>
  <suite name="test suite" duration-ms="218" started-at="2021-10-27T15:57:47 PDT" finished-at="2021-10-27T15:57:47 PDT">
    <groups>
    </groups>
    <test name="test" duration-ms="218" started-at="2021-10-27T15:57:47 PDT" finished-at="2021-10-27T15:57:47 PDT">
      <class name="testngdemos.TestngRetryDemo">
        <test-method status="PASS" signature="test1()[pri:0, instance:testngdemos.TestngRetryDemo@6dbb137d]" name="test1" duration-ms="101" started-at="2021-10-27T15:57:47 PDT" finished-at="2021-10-27T15:57:47 PDT">
          <reporter-output>
          </reporter-output>
        </test-method> <!-- test1 -->
        <test-method status="FAIL" signature="test2()[pri:0, instance:testngdemos.TestngRetryDemo@6dbb137d]" name="test2" duration-ms="5" started-at="2021-10-27T15:57:47 PDT" finished-at="2021-10-27T15:57:47 PDT">
          <exception class="java.lang.AssertionError">
            <message>
              <![CDATA[expected [true] but found [false]]]>
            </message>
            <full-stacktrace>
              <![CDATA[java.lang.AssertionError: expected [true] but found [false]
at org.testng.Assert.fail(Assert.java:99)
at org.testng.Assert.failNotEquals(Assert.java:1037)
at org.testng.Assert.assertTrue(Assert.java:45)
at org.testng.Assert.assertTrue(Assert.java:55)
at testngdemos.TestngRetryDemo.test2(TestngRetryDemo.java:16)
at sun.reflect.NativeMethodAccessorImpl.invoke0(Native Method)
at sun.reflect.NativeMethodAccessorImpl.invoke(NativeMethodAccessorImpl.java:62)
at sun.reflect.DelegatingMethodAccessorImpl.invoke(DelegatingMethodAccessorImpl.java:43)
at java.lang.reflect.Method.invoke(Method.java:498)
at org.testng.internal.MethodInvocationHelper.invokeMethod(MethodInvocationHelper.java:133)
at org.testng.internal.TestInvoker.invokeMethod(TestInvoker.java:598)
at org.testng.internal.TestInvoker.invokeTestMethod(TestInvoker.java:173)
at org.testng.internal.MethodRunner.runInSequence(MethodRunner.java:46)
at org.testng.internal.TestInvoker$MethodInvocationAgent.invoke(TestInvoker.java:824)
at org.testng.internal.TestInvoker.invokeTestMethods(TestInvoker.java:146)
at org.testng.internal.TestMethodWorker.invokeTestMethods(TestMethodWorker.java:146)
at org.testng.internal.TestMethodWorker.run(TestMethodWorker.java:128)
at java.util.ArrayList.forEach(ArrayList.java:1257)
at org.testng.TestRunner.privateRun(TestRunner.java:794)
at org.testng.TestRunner.run(TestRunner.java:596)
at org.testng.SuiteRunner.runTest(SuiteRunner.java:377)
at org.testng.SuiteRunner.access$000(SuiteRunner.java:28)
at org.testng.SuiteRunner$SuiteWorker.run(SuiteRunner.java:418)
at org.testng.internal.thread.ThreadUtil.lambda$execute$0(ThreadUtil.java:64)
at java.util.concurrent.FutureTask.run(FutureTask.java:266)
at java.util.concurrent.ThreadPoolExecutor.runWorker(ThreadPoolExecutor.java:1149)
at java.util.concurrent.ThreadPoolExecutor$Worker.run(ThreadPoolExecutor.java:624)
at java.lang.Thread.run(Thread.java:748)
]]>
            </full-stacktrace>
          </exception> <!-- java.lang.AssertionError -->
          <reporter-output>
          </reporter-output>
        </test-method> <!-- test2 -->
        <test-method status="PASS" signature="test3()[pri:0, instance:testngdemos.TestngRetryDemo@6dbb137d]" name="test3" duration-ms="2" started-at="2021-10-27T15:57:47 PDT" finished-at="2021-10-27T15:57:47 PDT">
          <reporter-output>
          </reporter-output>
        </test-method> <!-- test3 -->
      </class> <!-- testngdemos.TestngRetryDemo -->
    </test> <!-- test -->
  </suite> <!-- test suite -->
</testng-results>
